[32m[I 2022-01-04 02:12:37,781][39m A new study created in memory with name: my_study
[33m[W 2022-01-04 02:12:37,829][39m Trial 0 failed because of the following error: AttributeError("'dict' object has no attribute 'optimizer_name_model'")
Traceback (most recent call last):
  File "/home/puppy/anaconda3/envs/bci/lib/python3.9/site-packages/optuna/study/_optimize.py", line 213, in _run_trial
    value_or_values = func(trial)
  File "/tmp/ipykernel_91209/1582940388.py", line 24, in objective
    optimizer_model, optimizer_clf = get_optim(config, model, clf)
  File "/home/puppy/projects/BCI/utils/model_utils.py", line 20, in get_optim
    if config.optimizer_name_model == optimizer_names[0]:
AttributeError: 'dict' object has no attribute 'optimizer_name_model'